<?xml version="1.0" ?>
<!-- =================================================================================== -->
<!-- |    This document was autogenerated by xacro from msd700_blade_description.urdf.xacro | -->
<!-- |    EDITING THIS FILE BY HAND IS NOT RECOMMENDED                                 | -->
<!-- =================================================================================== -->
<robot name="msd700_blade">
  <!-- ================= BASE ================= -->
  <link name="base_footprint"/>
  <!-- Joint -->
  <joint name="base_joint" type="fixed">
    <parent link="base_footprint"/>
    <child link="base_link"/>
    <origin rpy="0 0 0" xyz="0 0 0.05"/>
  </joint>
  <!-- Link -->
  <link name="base_link">
    <visual>
      <origin rpy="0 0 1.5707963267948966" xyz="0 0 0"/>
      <geometry>
        <mesh filename="package://msd700_robot_description/isaac_sim/meshes/base_only.dae" scale="1 1 1"/>
      </geometry>
    </visual>
    <collision>
      <origin rpy="0 0 0" xyz="0 0 0.1"/>
      <geometry>
        <box size="0.866 0.47 0.271"/>
      </geometry>
    </collision>
    <inertial>
      <mass value="121.9"/>
      <origin rpy="0 0 0" xyz="0 0 0.1"/>
      <!-- the inertial matrix approximated as a box -->
      <!-- https://en.wikipedia.org/wiki/List_of_moments_of_inertia -->
      <inertia ixx="2.9900139916666664" ixy="0.0" ixz="0.0" iyy="8.364341191666666" iyz="0.0" izz="9.862278866666665"/>
    </inertial>
  </link>
  <!-- Joint -->
  <joint name="track_left_joint" type="fixed">
    <parent link="base_link"/>
    <child link="track_left_link"/>
    <origin rpy="0 0 0" xyz="-0.285 0.30 0.065"/>
  </joint>
  <!-- Link -->
  <link name="track_left_link">
    <visual>
      <origin rpy="0 0 3.141592653589793" xyz="0 0 0"/>
      <geometry>
        <mesh filename="package://msd700_robot_description/isaac_sim/meshes/left_track.dae" scale="1 1 1"/>
      </geometry>
    </visual>
    <collision>
      <origin rpy="0 0 0" xyz="0 0 0.1"/>
      <geometry>
        <box size="0.866 0.47 0.271"/>
      </geometry>
    </collision>
    <inertial>
      <mass value="121.9"/>
      <origin rpy="0 0 0" xyz="0 0 0.1"/>
      <!-- the inertial matrix approximated as a box -->
      <!-- https://en.wikipedia.org/wiki/List_of_moments_of_inertia -->
      <inertia ixx="2.9900139916666664" ixy="0.0" ixz="0.0" iyy="8.364341191666666" iyz="0.0" izz="9.862278866666665"/>
    </inertial>
  </link>
  <!-- Joint -->
  <joint name="track_right_joint" type="fixed">
    <parent link="base_link"/>
    <child link="track_right_link"/>
    <origin rpy="0 0 0" xyz="-0.285 -0.30 0.065"/>
  </joint>
  <!-- Link -->
  <link name="track_right_link">
    <visual>
      <origin rpy="0 0 3.141592653589793" xyz="0 0 0"/>
      <geometry>
        <mesh filename="package://msd700_robot_description/isaac_sim/meshes/left_track.dae" scale="1 1 1"/>
      </geometry>
    </visual>
    <collision>
      <origin rpy="0 0 0" xyz="0 0 0.1"/>
      <geometry>
        <box size="0.866 0.47 0.271"/>
      </geometry>
    </collision>
    <inertial>
      <mass value="121.9"/>
      <origin rpy="0 0 0" xyz="0 0 0.1"/>
      <!-- the inertial matrix approximated as a box -->
      <!-- https://en.wikipedia.org/wiki/List_of_moments_of_inertia -->
      <inertia ixx="2.9900139916666664" ixy="0.0" ixz="0.0" iyy="8.364341191666666" iyz="0.0" izz="9.862278866666665"/>
    </inertial>
  </link>
  <!-- Joint -->
  <joint name="wheel_fl_joint" type="continuous">
    <parent link="base_link"/>
    <child link="wheel_fl_link"/>
    <origin rpy="0 0 0" xyz="0.305 0.30 0.065"/>
    <axis xyz="0 1 0"/>
  </joint>
  <!-- Link -->
  <link name="wheel_fl_link">
    <visual>
      <origin rpy="0 0 1.5707963267948966" xyz="0.11050000000000001 -0.04 -0.11050000000000001"/>
      <geometry>
        <mesh filename="package://msd700_robot_description/isaac_sim/meshes/wheel.stl" scale="0.001 0.001 0.001"/>
      </geometry>
      <material name="White">
        <color rgba="1 1 1 1.0"/>
      </material>
    </visual>
    <collision>
      <origin rpy="1.5707963267948966 1.5707963267948966 0" xyz="0 0 0"/>
      <geometry>
        <cylinder length="0.1" radius="0.1355"/>
      </geometry>
    </collision>
    <inertial>
      <origin rpy="1.5707963267948966 0 0" xyz="0 0 0"/>
      <mass value="2"/>
      <inertia ixx="0.010846791666666668" ixy="0" ixz="0" iyy="0.010846791666666668" iyz="0" izz="0.01836025"/>
    </inertial>
  </link>
  <!-- Joint -->
  <joint name="wheel_fr_joint" type="continuous">
    <parent link="base_link"/>
    <child link="wheel_fr_link"/>
    <origin rpy="0 0 0" xyz="0.305 -0.30 0.065"/>
    <axis xyz="0 1 0"/>
  </joint>
  <!-- Link -->
  <link name="wheel_fr_link">
    <visual>
      <origin rpy="0 0 1.5707963267948966" xyz="0.11050000000000001 -0.04 -0.11050000000000001"/>
      <geometry>
        <mesh filename="package://msd700_robot_description/isaac_sim/meshes/wheel.stl" scale="0.001 0.001 0.001"/>
      </geometry>
      <material name="White">
        <color rgba="1 1 1 1.0"/>
      </material>
    </visual>
    <collision>
      <origin rpy="1.5707963267948966 1.5707963267948966 0" xyz="0 0 0"/>
      <geometry>
        <cylinder length="0.1" radius="0.1355"/>
      </geometry>
    </collision>
    <inertial>
      <origin rpy="1.5707963267948966 0 0" xyz="0 0 0"/>
      <mass value="2"/>
      <inertia ixx="0.010846791666666668" ixy="0" ixz="0" iyy="0.010846791666666668" iyz="0" izz="0.01836025"/>
    </inertial>
  </link>
  <!-- Joint -->
  <joint name="wheel_rl_joint" type="continuous">
    <parent link="base_link"/>
    <child link="wheel_rl_link"/>
    <origin rpy="0 0 0" xyz="-0.285 0.30 0.065"/>
    <axis xyz="0 1 0"/>
  </joint>
  <!-- Link -->
  <link name="wheel_rl_link">
    <visual>
      <origin rpy="0 0 1.5707963267948966" xyz="0.11050000000000001 -0.04 -0.11050000000000001"/>
      <geometry>
        <mesh filename="package://msd700_robot_description/isaac_sim/meshes/wheel.stl" scale="0.001 0.001 0.001"/>
      </geometry>
      <material name="White">
        <color rgba="1 1 1 1.0"/>
      </material>
    </visual>
    <collision>
      <origin rpy="1.5707963267948966 1.5707963267948966 0" xyz="0 0 0"/>
      <geometry>
        <cylinder length="0.1" radius="0.1355"/>
      </geometry>
    </collision>
    <inertial>
      <origin rpy="1.5707963267948966 0 0" xyz="0 0 0"/>
      <mass value="2"/>
      <inertia ixx="0.010846791666666668" ixy="0" ixz="0" iyy="0.010846791666666668" iyz="0" izz="0.01836025"/>
    </inertial>
  </link>
  <!-- Joint -->
  <joint name="wheel_rr_joint" type="continuous">
    <parent link="base_link"/>
    <child link="wheel_rr_link"/>
    <origin rpy="0 0 0" xyz="-0.285 -0.30 0.065"/>
    <axis xyz="0 1 0"/>
  </joint>
  <!-- Link -->
  <link name="wheel_rr_link">
    <visual>
      <origin rpy="0 0 1.5707963267948966" xyz="0.11050000000000001 -0.04 -0.11050000000000001"/>
      <geometry>
        <mesh filename="package://msd700_robot_description/isaac_sim/meshes/wheel.stl" scale="0.001 0.001 0.001"/>
      </geometry>
      <material name="White">
        <color rgba="1 1 1 1.0"/>
      </material>
    </visual>
    <collision>
      <origin rpy="1.5707963267948966 1.5707963267948966 0" xyz="0 0 0"/>
      <geometry>
        <cylinder length="0.1" radius="0.1355"/>
      </geometry>
    </collision>
    <inertial>
      <origin rpy="1.5707963267948966 0 0" xyz="0 0 0"/>
      <mass value="2"/>
      <inertia ixx="0.010846791666666668" ixy="0" ixz="0" iyy="0.010846791666666668" iyz="0" izz="0.01836025"/>
    </inertial>
  </link>
  <joint name="blade_base_joint" type="fixed">
    <parent link="base_link"/>
    <child link="blade_base_link"/>
    <origin rpy="0 0 0" xyz="0.1 0 0.23"/>
  </joint>
  <link name="blade_base_link">
    <visual>
      <origin rpy="1.5707963267948966 0 1.5707963267948966" xyz="0 0 0"/>
      <geometry>
        <mesh filename="package://msd700_robot_description/isaac_sim/meshes/blade_base.dae" scale="1 1 1"/>
      </geometry>
      <material name="Gray">
        <color rgba="0.7 0.7 0.7 1.0"/>
      </material>
    </visual>
    <collision>
      <origin rpy="0 0 0" xyz="0 0 0"/>
      <geometry>
        <box size="0.566 0.47 0.01"/>
      </geometry>
    </collision>
    <inertial>
      <origin rpy="0 0 0" xyz="0 0 0"/>
      <mass value="8"/>
      <inertia ixx="0.14733333333333332" ixy="0.0" ixz="0.0" iyy="0.21363733333333326" iyz="0.0" izz="0.3608373333333333"/>
    </inertial>
  </link>
  <joint name="blade_joint" type="revolute">
    <parent link="blade_base_link"/>
    <child link="blade_link"/>
    <origin rpy="0 0 0" xyz="0.32 0 0"/>
    <axis xyz="0 1 0"/>
    <limit effort="0.0" lower="0.0" upper="-0.5" velocity="0.0"/>
  </joint>
  <link name="blade_link">
    <visual>
      <origin rpy="1.5707963267948966 0 1.5707963267948966" xyz="-0.315 0 0"/>
      <geometry>
        <mesh filename="package://msd700_robot_description/isaac_sim/meshes/blade.dae" scale="1 1 1"/>
      </geometry>
      <material name="Gray">
        <color rgba="0.7 0.7 0.7 1.0"/>
      </material>
    </visual>
    <collision>
      <origin rpy="1.5707963267948966 0 1.5707963267948966" xyz="-0.315 0 0"/>
      <geometry>
        <mesh filename="package://msd700_robot_description/isaac_sim/meshes/blade.dae" scale="1 1 1"/>
      </geometry>
    </collision>
    <inertial>
      <origin rpy="0 0 0" xyz="0.2 0 -0.12"/>
      <mass value="5"/>
      <inertia ixx="0.23126041666666663" ixy="0.0" ixz="0.0" iyy="0.028593750000000005" iyz="0.0" izz="0.20566666666666664"/>
    </inertial>
  </link>
  <!-- ================= SENSOR ================= -->
  <joint name="sensor_box_joint" type="fixed">
    <parent link="base_link"/>
    <child link="sensor_box_link"/>
    <origin rpy="0 0 0" xyz="0.08300000000000002 0.13 0.23"/>
  </joint>
  <link name="sensor_box_link">
    <visual>
      <origin rpy="0 0 0" xyz="0 0 0.075"/>
      <geometry>
        <box size="0.3 0.15 0.15"/>
      </geometry>
      <material name="Gray">
        <color rgba="0.7 0.7 0.7 1.0"/>
      </material>
    </visual>
    <collision>
      <origin rpy="0 0 0" xyz="0.08300000000000002 0.13 0.075"/>
      <geometry>
        <box size="0.3 0.15 0.15"/>
      </geometry>
      <material name="Gray">
        <color rgba="0.7 0.7 0.7 1.0"/>
      </material>
    </collision>
    <inertial>
      <origin rpy="0 0 0" xyz="0 0 0.075"/>
      <mass value="0.85"/>
      <inertia ixx="0.0031875" ixy="0.0" ixz="0.0" iyy="0.007968749999999998" iyz="0.0" izz="0.007968749999999998"/>
    </inertial>
  </link>
  <!-- Joint -->
  <joint name="livox_joint" type="fixed">
    <parent link="sensor_box_link"/>
    <child link="livox_link"/>
    <origin rpy="0 0 0" xyz="-0.1175 -0.042499999999999996 0.18"/>
  </joint>
  <!-- Link -->
  <link name="livox_link">
    <visual>
      <origin rpy="0 0 -1.5707963267948966" xyz="0 0 0"/>
      <geometry>
        <mesh filename="package://msd700_robot_description/isaac_sim/meshes/livox_360.dae" scale="1 1 1"/>
      </geometry>
    </visual>
    <collision>
      <origin rpy="0 0 0" xyz="0 0 0"/>
      <geometry>
        <box size="0.065 0.065 0.06"/>
      </geometry>
    </collision>
    <inertial>
      <mass value="0.265"/>
      <origin rpy="0 0 0" xyz="0 0 0"/>
      <!-- the inertial matrix approximated as a box -->
      <!-- https://en.wikipedia.org/wiki/List_of_moments_of_inertia -->
      <inertia ixx="0.00017280208333333335" ixy="0.0" ixz="0.0" iyy="0.00017280208333333335" iyz="0.0" izz="0.00018660416666666668"/>
    </inertial>
  </link>
</robot>
